Workbook

Sheet 🏠 Painel Geral
B2: GLAUBER — ORÇAMENTO PRÉ-INCUBAÇÃO (6 MESES)
B3: Plano Financeiro: Bootstrapping + FFF + Crowdfunding → Investidor Anjo
B4: 🔵 Azul = fórmula / cálculo 🟡 Amarelo = input editável 🟢 Verde = referência entre abas
B6: PREMISSAS — EDITE OS CAMPOS AMARELOS
B7: Pró-labore por sócio (mensal) | C7: 2500 | D7: Mínimo recomendado para atingir Fator R ≥28% e ficar no Anexo III do Simples (alíquota 6%)
B8: Quantidade de sócios | C8: 2 | D8: Preencha conforme quadro societário
B9: Desenvolvedor (freelancer/júnior) | C9: 2000 | D9: Terceira pessoa — pode ser freela por projeto
B10: Estagiário / marketing | C10: 800 | D10: Apoio em redes sociais e validação com produtoras
B11: Verba marketing / ads (mensal) | C11: 500 | D11: Meta Ads, conteúdo, material para festivais
B12: Eventos / networking Porto Digital | C12: 150 | D12: Inscrições, transporte, happy hours
B13: Servidor / Nuvem (AWS, Fly, Vercel) | C13: 300 | D13: Inclui compute + logs. Escala conforme uso
B14: Banco de dados gerenciado | C14: 100 | D14: PostgreSQL RDS ou Supabase
B15: Storage (S3 — vídeos e assets) | C15: 80 | D15: Para os 3 projetos de curtas-metragens
B16: Ferramentas (Notion, Figma, Linear, CI) | C16: 150 | D16: Produtividade e gestão de produto
B17: Email transacional (Resend/SES) | C17: 50 | D17: Comunicação com usuários das produtoras
B18: Contador mensal | C18: 450 | D18: Essencial: DAS, pró-labore, obrigações mensais
... B21: Coworking / escritório virtual Recife | C21: 200 | D21: Endereço fiscal + salas de reunião (útil para INPI)
B23: CÁLCULOS AUTOMÁTICOS
B24: Total folha de pagamento (mensal) | C24: =C7*C8+C9+C10 -> 7800 | D24: Pró-labore sócios + dev + estagiário
B25: INSS sobre pró-labore (11%) | C25: =C7*C8*0.11 -> 550 | D25: Alíquota INSS sobre pró-labore dos sócios
B26: Total infraestrutura (mensal) | C26: =C13+C14+C15+C16+C17 -> 680 | D26: Soma de todos os custos de cloud e ferramentas
B27: Total admin/jurídico (mensal) | C27: =C18+C19+C20+C21+C25 -> 1400 | D27: Contador + DAS + domínio + coworking + INSS
B28: Total marketing (mensal) | C28: =C11+C12 -> 650 | D28: Ads + eventos
B29: CUSTO OPERACIONAL MENSAL TOTAL | C29: =C24+C26+C27+C28 -> 10530 | D29: Soma de todas as categorias mensais
B31: CUSTOS ÚNICOS DE ABERTURA (MÊS 1)
B32: Taxa JUCEPE — Registro LTDA | C32: 396 | D32: Fonte: Tabela JUCEPE 2025 — taxa estadual obrigatória para constituição de LTDA
B33: Alvará Prefeitura Recife | C33: 512 | D33: Fonte: Tabela de Taxas de Licenças Prefeitura Recife 2025 (valor base)
B34: Certificado e-CPF — 2 sócios (A1 1 ano) | C34: 300 | D34: R$150 por sócio. Necessário para assinar digitalmente na JUCEPE
B35: Certificado e-CNPJ (empresa, A1 1 ano) | C35: 220 | D35: Necessário para emitir NFS-e na Prefeitura do Recife
B36: Honorários contador — abertura | C36: 900 | D36: Média mercado Recife. Muitos isentam se fechar contrato anual
B37: Registro de Marca INPI — 2 classes | C37: 880 | D37: Classe 42 (software) + Classe 35 (gestão). Com desconto 50% ME/EPP (R$440 × 2)
B38: TOTAL ABERTURA (mês 1) | C38: =SUM(C32:C37) -> 3208
B39: RESUMO FINANCEIRO — 6 MESES
B40: Categoria | C40: Mês 1 (abertura) | D40: Mês 2 | E40: Mês 3 | F40: Mês 4 | G40: Mês 5 | H40: Mês 6 (pitch anjo)
B41: Custos de Abertura | C41: =C38 -> 3208 | D41: 0 | E41: 0 | F41: 0 | G41: 0 | H41: 0
B42: Folha de Pagamento | C42: =C24 -> 7800 | D42: =C24 -> 7800 | E42: =C24 -> 7800 | F42: =C24 -> 7800 | G42: =C24 -> 7800 | H42: =C24 -> 7800
B43: Infraestrutura (cloud) | C43: =C26 -> 680 | D43: =C26 -> 680 | E43: =C26 -> 680 | F43: =C26 -> 680 | G43: =C26 -> 680 | H43: =C26 -> 680
B44: Admin / Jurídico / Fiscal | C44: =C27 -> 1400 | D44: =C27 -> 1400 | E44: =C27 -> 1400 | F44: =C27 -> 1400 | G44: =C27 -> 1400 | H44: =C27 -> 1400
B45: Marketing & Eventos | C45: =C28 -> 650 | D45: =C28 -> 650 | E45: =C28 -> 650 | F45: =C28 -> 650 | G45: =C28 -> 650 | H45: =C28 -> 650
B46: TOTAL POR MÊS | C46: =SUM(C41:C45) -> 13738 | D46: =SUM(D41:D45) -> 10530 | E46: =SUM(E41:E45) -> 10530 | F46: =SUM(F41:F45) -> 10530 | G46: =SUM(G41:G45) -> 10530 | H46: =SUM(H41:H45) -> 10530
...

Sheet 📋 Abertura e Legalização
B2: GLAUBER — CUSTOS DE ABERTURA E LEGALIZAÇÃO
B3: Referências: JUCEPE 2025 · Prefeitura Recife 2025 · INPI 2025 · Mercado Recife
B5: 1. ABERTURA DO CNPJ LTDA — Junta Comercial PE (JUCEPE)
B6: Passo 1 | C6: Certificado Digital e-CPF (A1, 1 ano) — por sócio | D6: R$ 150,00 | E6: Necessário para assinar digitalmente na JUCEPE. Prazo: imediato
B7: Passo 2 | C7: Consulta de Viabilidade (nome e endereço) | D7: Gratuito | E7: Portal JUCEPE — verifica nome e CNAE no endereço escolhido
B8: Passo 3 | C8: DBE — Documento Básico de Entrada (Receita Federal) | D8: Gratuito | E8: Pedido oficial de criação do CNPJ via Coletor Nacional
B9: Passo 4 | C9: Taxa JUCEPE — Registro do Contrato Social LTDA | D9: R$ 396,00 | E9: Taxa estadual. Prazo aprovação: 3–5 dias úteis após pagamento
B10: Passo 5 | C10: Alvará Localização e Funcionamento — Prefeitura Recife | D10: R$ 511,67 | E10: Portal Licenciamento Unificado PCR. Atividade de baixo risco — sem vistoria prévia
B11: Passo 6 | C11: Certificado e-CNPJ (A1, 1 ano) — empresa | D11: R$ 220,00 | E11: Necessário para emitir NFS-e no portal da Prefeitura do Recife
B12: Passo 7 | C12: Enquadramento Simples Nacional (contador) | D12: Incluso nos honorários | E12: Solicitar em até 30 dias da inscrição municipal, máx. 60 dias do CNPJ
B13: ⚠ ATENÇÃO — FATOR R: Planeje o pró-labore para ≥ 28% do faturamento → Anexo III (6%) em vez do Anexo V (15,5%)
B15: 2. HONORÁRIOS CONTÁBEIS
B16: Honorários de Abertura (taxa única) | C16: R$ 600 a R$ 1.200 | D16: Varia por escritório. Alguns isentam ao fechar contrato mensal anual
B17: Honorários Mensais (manutenção) | C17: R$ 300 a R$ 600 | D17: DAS, folha, obrigações acessórias. Recomendado desde o 1º mês
B20: 3. REGISTRO DE MARCA INPI — Aplicativo 'Glauber'
B21: Busca de Anterioridade | C21: Gratuito | D21: Acesse busca.inpi.gov.br — buscar 'Glauber' nas classes 42 e 35 antes de depositar
B22: Cadastro no e-INPI | C22: Gratuito | D22: gov.br/inpi — necessário para protocolar o pedido
B23: GRU 389 Classe 42 (software/SaaS) | C23: R$ 440,00 | D23: Com desconto 50% ME/EPP. Cobre 'Software como Serviço [SaaS]' e desenvolvimento
B24: GRU 389 Classe 35 (gestão negóc.) | C24: R$ 440,00 | D24: Com desconto 50% ME/EPP. Cobre gestão e administração de produções
B25: Acompanhamento RPI (semanal) | C25: Gratuito | D25: Revista da Propriedade Industrial — publicada toda terça-feira. Verifique número do processo
B26: INPI Recife — atendimento | C26: Presencial | D26: Av. Jorn. Aníbal Fernandes s/n, Sala 307, Cidade Universitária. E-mail: superintendencia.nordeste@inpi.gov.br
B28: RESUMO DE CUSTOS — ABERTURA
B29: Taxa JUCEPE | C29: 396
B30: Alvará Prefeitura Recife | C30: 512
B31: e-CPF (2 sócios) | C31: 300
B32: e-CNPJ (empresa) | C32: 220
B33: Honorários contador abertura | C33: 900
B34: Marca INPI (2 classes c/ desc.) | C34: 880
B35: TOTAL ABERTURA (estimativa 2025) | C35: =SUM(C29:C34) -> 3208

Sheet 📅 Mês 1
B2: GLAUBER — MÊS 1
B3: Foco: Abertura do CNPJ, Registro de marca, setup inicial
B5: EQUIPE — FOLHA DE PAGAMENTO
B6: Pró-labore sócio 1 | C6: ='🏠 Painel Geral'!C7 -> 2500 | E6: Retirada mensal do sócio fundador. Sujeito a INSS
B7: Pró-labore sócio 2 | C7: ='🏠 Painel Geral'!C7 -> 2500 | E7: Retirada mensal do co-fundador. Sujeito a INSS
B8: Desenvolvedor (freela/júnior) | C8: ='🏠 Painel Geral'!C9 -> 2000 | E8: Terceira pessoa — produto e código
B9: Estagiário / marketing | C9: ='🏠 Painel Geral'!C10 -> 800 | E9: Redes sociais, conteúdo e suporte às produtoras
B10: INSS pró-labore (11%) | C10: ='🏠 Painel Geral'!C7*'🏠 Painel Geral'!C8*0.11 -> 550 | E10: Encargo patronal sobre pró-labore
B11: Subtotal Equipe | C11: =SUM(C6:C10) -> 8350
B12: INFRAESTRUTURA & PRODUTO
B13: Servidor / Nuvem | C13: ='🏠 Painel Geral'!C13 -> 300 | E13: AWS / Vercel / Fly.io
B14: Banco de dados gerenciado | C14: ='🏠 Painel Geral'!C14 -> 100 | E14: PostgreSQL RDS ou Supabase
B15: Storage (vídeos/assets) | C15: ='🏠 Painel Geral'!C15 -> 80 | E15: S3 — arquivos das produtoras
B16: Ferramentas (Notion/Figma) | C16: ='🏠 Painel Geral'!C16 -> 150 | E16: Produtividade, design, CI/CD
B17: Email transacional | C17: ='🏠 Painel Geral'!C17 -> 50 | E17: Resend ou Amazon SES
B18: Subtotal Infra | C18: =SUM(C13:C17) -> 680
B19: ADMINISTRATIVO / JURÍDICO / FISCAL
B20: Custos de Abertura (mês 1 apenas) | C20: ='📋 Abertura e Legalização'!C35 -> 3208 | E20: Apenas no mês 1
B21: Contador mensal | C21: ='🏠 Painel Geral'!C18 -> 450 | E21: DAS, folha, obrigações acessórias
B22: DAS Simples Nacional | C22: ='🏠 Painel Geral'!C19 -> 150 | E22: Guia mensal de impostos (estimativa)
B23: Domínio + landing page | C23: ='🏠 Painel Geral'!C20 -> 50 | E23: Registro .com.br + hospedagem
B24: Coworking / end. fiscal | C24: ='🏠 Painel Geral'!C21 -> 200 | E24: Endereço Recife + sala de reunião
B25: Subtotal Admin | C25: =SUM(C20:C24) -> 4058
B26: MARKETING & VALIDAÇÃO
B27: Verba ads / conteúdo | C27: ='🏠 Painel Geral'!C11 -> 500 | E27: Meta Ads, material gráfico, festival
B28: Eventos / networking | C28: ='🏠 Painel Geral'!C12 -> 150 | E28: Porto Digital, festivais de cinema PE
B29: Subtotal Marketing | C29: =SUM(C27:C28) -> 650
B31: TOTAL GERAL — Mês 1 | C31: =C11+C18+C25+C29 -> 13738
B32: METAS E MARCOS — Mês 1
B33: ✅ CNPJ LTDA aberto e aprovado pela JUCEPE
B34: ✅ Alvará Prefeitura Recife emitido
B35: ✅ Pedido de registro da marca Glauber protocolado no INPI
B36: ✅ Conta PJ separada aberta (separação PJ x PF — obrigatório!)
B37: ✅ Pró-labore configurado com INSS
B38: ✅ Contrato com contador assinado
B40: 🟡 Amarelo = input editável no Painel Geral 🟢 Verde = valor referenciado do Painel 🔵 Azul = fórmula calculada

Sheet 📅 Mês 2
B2: GLAUBER — MÊS 2
B3: Foco: Validação do protótipo — 1º curta-metragem
B5: EQUIPE — FOLHA DE PAGAMENTO
B6: Pró-labore sócio 1 | C6: ='🏠 Painel Geral'!C7 -> 2500 | E6: Retirada mensal do sócio fundador. Sujeito a INSS
B7: Pró-labore sócio 2 | C7: ='🏠 Painel Geral'!C7 -> 2500 | E7: Retirada mensal do co-fundador. Sujeito a INSS
B8: Desenvolvedor (freela/júnior) | C8: ='🏠 Painel Geral'!C9 -> 2000 | E8: Terceira pessoa — produto e código
B9: Estagiário / marketing | C9: ='🏠 Painel Geral'!C10 -> 800 | E9: Redes sociais, conteúdo e suporte às produtoras
B10: INSS pró-labore (11%) | C10: ='🏠 Painel Geral'!C7*'🏠 Painel Geral'!C8*0.11 -> 550 | E10: Encargo patronal sobre pró-labore
B11: Subtotal Equipe | C11: =SUM(C6:C10) -> 8350
B12: INFRAESTRUTURA & PRODUTO
B13: Servidor / Nuvem | C13: ='🏠 Painel Geral'!C13 -> 300 | E13: AWS / Vercel / Fly.io
B14: Banco de dados gerenciado | C14: ='🏠 Painel Geral'!C14 -> 100 | E14: PostgreSQL RDS ou Supabase
B15: Storage (vídeos/assets) | C15: ='🏠 Painel Geral'!C15 -> 80 | E15: S3 — arquivos das produtoras
B16: Ferramentas (Notion/Figma) | C16: ='🏠 Painel Geral'!C16 -> 150 | E16: Produtividade, design, CI/CD
B17: Email transacional | C17: ='🏠 Painel Geral'!C17 -> 50 | E17: Resend ou Amazon SES
B18: Subtotal Infra | C18: =SUM(C13:C17) -> 680
B19: ADMINISTRATIVO / JURÍDICO / FISCAL
B20: Contador mensal | C20: ='🏠 Painel Geral'!C18 -> 450 | E20: DAS, folha, obrigações acessórias
B21: DAS Simples Nacional | C21: ='🏠 Painel Geral'!C19 -> 150 | E21: Guia mensal de impostos (estimativa)
B22: Domínio + landing page | C22: ='🏠 Painel Geral'!C20 -> 50 | E22: Registro .com.br + hospedagem
B23: Coworking / end. fiscal | C23: ='🏠 Painel Geral'!C21 -> 200 | E23: Endereço Recife + sala de reunião
B24: Subtotal Admin | C24: =SUM(C20:C23) -> 850
B25: MARKETING & VALIDAÇÃO
B26: Verba ads / conteúdo | C26: ='🏠 Painel Geral'!C11 -> 500 | E26: Meta Ads, material gráfico, festival
B27: Eventos / networking | C27: ='🏠 Painel Geral'!C12 -> 150 | E27: Porto Digital, festivais de cinema PE
B28: Subtotal Marketing | C28: =SUM(C26:C27) -> 650
B30: TOTAL GERAL — Mês 2 | C30: =C11+C18+C24+C28 -> 10530
B31: METAS E MARCOS — Mês 2
B32: 🎬 Integrar plataforma com produtora 1 (curta-metragem)
B33: 📊 Mapear fluxo de produção e dores reais do usuário
B34: 📝 Documentar feedbacks qualitativos (entrevistas)
B35: 🖥 Estabilidade de servidor: uptime > 95%
B36: 📣 Publicar 2 posts/semana no Instagram (bastidores do desenvolvimento)
B38: 🟡 Amarelo = input editável no Painel Geral 🟢 Verde = valor referenciado do Painel 🔵 Azul = fórmula calculada

Sheet 📅 Mês 3
B2: GLAUBER — MÊS 3
B3: Foco: Validação — 2º e 3º curtas-metragens
B5: EQUIPE — FOLHA DE PAGAMENTO
B6: Pró-labore sócio 1 | C6: ='🏠 Painel Geral'!C7 -> 2500 | E6: Retirada mensal do sócio fundador. Sujeito a INSS
B7: Pró-labore sócio 2 | C7: ='🏠 Painel Geral'!C7 -> 2500 | E7: Retirada mensal do co-fundador. Sujeito a INSS
B8: Desenvolvedor (freela/júnior) | C8: ='🏠 Painel Geral'!C9 -> 2000 | E8: Terceira pessoa — produto e código
B9: Estagiário / marketing | C9: ='🏠 Painel Geral'!C10 -> 800 | E9: Redes sociais, conteúdo e suporte às produtoras
B10: INSS pró-labore (11%) | C10: ='🏠 Painel Geral'!C7*'🏠 Painel Geral'!C8*0.11 -> 550 | E10: Encargo patronal sobre pró-labore
B11: Subtotal Equipe | C11: =SUM(C6:C10) -> 8350
B12: INFRAESTRUTURA & PRODUTO
B13: Servidor / Nuvem | C13: ='🏠 Painel Geral'!C13 -> 300 | E13: AWS / Vercel / Fly.io
B14: Banco de dados gerenciado | C14: ='🏠 Painel Geral'!C14 -> 100 | E14: PostgreSQL RDS ou Supabase
B15: Storage (vídeos/assets) | C15: ='🏠 Painel Geral'!C15 -> 80 | E15: S3 — arquivos das produtoras
B16: Ferramentas (Notion/Figma) | C16: ='🏠 Painel Geral'!C16 -> 150 | E16: Produtividade, design, CI/CD
B17: Email transacional | C17: ='🏠 Painel Geral'!C17 -> 50 | E17: Resend ou Amazon SES
B18: Subtotal Infra | C18: =SUM(C13:C17) -> 680
B19: ADMINISTRATIVO / JURÍDICO / FISCAL
B20: Contador mensal | C20: ='🏠 Painel Geral'!C18 -> 450 | E20: DAS, folha, obrigações acessórias
B21: DAS Simples Nacional | C21: ='🏠 Painel Geral'!C19 -> 150 | E21: Guia mensal de impostos (estimativa)
B22: Domínio + landing page | C22: ='🏠 Painel Geral'!C20 -> 50 | E22: Registro .com.br + hospedagem
B23: Coworking / end. fiscal | C23: ='🏠 Painel Geral'!C21 -> 200 | E23: Endereço Recife + sala de reunião
B24: Subtotal Admin | C24: =SUM(C20:C23) -> 850
B25: MARKETING & VALIDAÇÃO
B26: Verba ads / conteúdo | C26: ='🏠 Painel Geral'!C11 -> 500 | E26: Meta Ads, material gráfico, festival
B27: Eventos / networking | C27: ='🏠 Painel Geral'!C12 -> 150 | E27: Porto Digital, festivais de cinema PE
B28: Subtotal Marketing | C28: =SUM(C26:C27) -> 650
B30: TOTAL GERAL — Mês 3 | C30: =C11+C18+C24+C28 -> 10530
B31: METAS E MARCOS — Mês 3
B32: 🎬 Integrar produtoras 2 e 3 (curtas-metragens)
B33: 📊 Coletar dados de uso: DAU, features mais usadas, churn
B34: 🔧 Iterar produto com base em feedbacks dos 3 projetos
B35: 💬 Coletar depoimentos e NPS das equipes
B37: 🟡 Amarelo = input editável no Painel Geral 🟢 Verde = valor referenciado do Painel 🔵 Azul = fórmula calculada

Sheet 📅 Mês 4
B2: GLAUBER — MÊS 4
B3: Foco: Ajustes de produto com base no feedback das produtoras
B5: EQUIPE — FOLHA DE PAGAMENTO
B6: Pró-labore sócio 1 | C6: ='🏠 Painel Geral'!C7 -> 2500 | E6: Retirada mensal do sócio fundador. Sujeito a INSS
B7: Pró-labore sócio 2 | C7: ='🏠 Painel Geral'!C7 -> 2500 | E7: Retirada mensal do co-fundador. Sujeito a INSS
B8: Desenvolvedor (freela/júnior) | C8: ='🏠 Painel Geral'!C9 -> 2000 | E8: Terceira pessoa — produto e código
B9: Estagiário / marketing | C9: ='🏠 Painel Geral'!C10 -> 800 | E9: Redes sociais, conteúdo e suporte às produtoras
B10: INSS pró-labore (11%) | C10: ='🏠 Painel Geral'!C7*'🏠 Painel Geral'!C8*0.11 -> 550 | E10: Encargo patronal sobre pró-labore
B11: Subtotal Equipe | C11: =SUM(C6:C10) -> 8350
B12: INFRAESTRUTURA & PRODUTO
B13: Servidor / Nuvem | C13: ='🏠 Painel Geral'!C13 -> 300 | E13: AWS / Vercel / Fly.io
B14: Banco de dados gerenciado | C14: ='🏠 Painel Geral'!C14 -> 100 | E14: PostgreSQL RDS ou Supabase
B15: Storage (vídeos/assets) | C15: ='🏠 Painel Geral'!C15 -> 80 | E15: S3 — arquivos das produtoras
B16: Ferramentas (Notion/Figma) | C16: ='🏠 Painel Geral'!C16 -> 150 | E16: Produtividade, design, CI/CD
B17: Email transacional | C17: ='🏠 Painel Geral'!C17 -> 50 | E17: Resend ou Amazon SES
B18: Subtotal Infra | C18: =SUM(C13:C17) -> 680
B19: ADMINISTRATIVO / JURÍDICO / FISCAL
B20: Contador mensal | C20: ='🏠 Painel Geral'!C18 -> 450 | E20: DAS, folha, obrigações acessórias
B21: DAS Simples Nacional | C21: ='🏠 Painel Geral'!C19 -> 150 | E21: Guia mensal de impostos (estimativa)
B22: Domínio + landing page | C22: ='🏠 Painel Geral'!C20 -> 50 | E22: Registro .com.br + hospedagem
B23: Coworking / end. fiscal | C23: ='🏠 Painel Geral'!C21 -> 200 | E23: Endereço Recife + sala de reunião
B24: Subtotal Admin | C24: =SUM(C20:C23) -> 850
B25: MARKETING & VALIDAÇÃO
B26: Verba ads / conteúdo | C26: ='🏠 Painel Geral'!C11 -> 500 | E26: Meta Ads, material gráfico, festival
B27: Eventos / networking | C27: ='🏠 Painel Geral'!C12 -> 150 | E27: Porto Digital, festivais de cinema PE
B28: Subtotal Marketing | C28: =SUM(C26:C27) -> 650
B30: TOTAL GERAL — Mês 4 | C30: =C11+C18+C24+C28 -> 10530
B31: METAS E MARCOS — Mês 4
B32: 🔧 Implementar melhorias prioritárias identificadas nos testes
B33: 📈 Definir métricas-chave: TAM/SAM/SOM para o pitch
B34: 💰 Avaliar faturamento inicial (primeiras receitas / LOIs)
B35: 🏆 Participar de evento Porto Digital / Pernambuco Digital
B37: 🟡 Amarelo = input editável no Painel Geral 🟢 Verde = valor referenciado do Painel 🔵 Azul = fórmula calculada

Sheet 📅 Mês 5
B2: GLAUBER — MÊS 5
B3: Foco: Preparação do deck e materiais para o investidor anjo
B5: EQUIPE — FOLHA DE PAGAMENTO
B6: Pró-labore sócio 1 | C6: ='🏠 Painel Geral'!C7 -> 2500 | E6: Retirada mensal do sócio fundador. Sujeito a INSS
B7: Pró-labore sócio 2 | C7: ='🏠 Painel Geral'!C7 -> 2500 | E7: Retirada mensal do co-fundador. Sujeito a INSS
B8: Desenvolvedor (freela/júnior) | C8: ='🏠 Painel Geral'!C9 -> 2000 | E8: Terceira pessoa — produto e código
B9: Estagiário / marketing | C9: ='🏠 Painel Geral'!C10 -> 800 | E9: Redes sociais, conteúdo e suporte às produtoras
B10: INSS pró-labore (11%) | C10: ='🏠 Painel Geral'!C7*'🏠 Painel Geral'!C8*0.11 -> 550 | E10: Encargo patronal sobre pró-labore
B11: Subtotal Equipe | C11: =SUM(C6:C10) -> 8350
B12: INFRAESTRUTURA & PRODUTO
B13: Servidor / Nuvem | C13: ='🏠 Painel Geral'!C13 -> 300 | E13: AWS / Vercel / Fly.io
B14: Banco de dados gerenciado | C14: ='🏠 Painel Geral'!C14 -> 100 | E14: PostgreSQL RDS ou Supabase
B15: Storage (vídeos/assets) | C15: ='🏠 Painel Geral'!C15 -> 80 | E15: S3 — arquivos das produtoras
B16: Ferramentas (Notion/Figma) | C16: ='🏠 Painel Geral'!C16 -> 150 | E16: Produtividade, design, CI/CD
B17: Email transacional | C17: ='🏠 Painel Geral'!C17 -> 50 | E17: Resend ou Amazon SES
B18: Subtotal Infra | C18: =SUM(C13:C17) -> 680
B19: ADMINISTRATIVO / JURÍDICO / FISCAL
B20: Contador mensal | C20: ='🏠 Painel Geral'!C18 -> 450 | E20: DAS, folha, obrigações acessórias
B21: DAS Simples Nacional | C21: ='🏠 Painel Geral'!C19 -> 150 | E21: Guia mensal de impostos (estimativa)
B22: Domínio + landing page | C22: ='🏠 Painel Geral'!C20 -> 50 | E22: Registro .com.br + hospedagem
B23: Coworking / end. fiscal | C23: ='🏠 Painel Geral'!C21 -> 200 | E23: Endereço Recife + sala de reunião
B24: Subtotal Admin | C24: =SUM(C20:C23) -> 850
B25: MARKETING & VALIDAÇÃO
B26: Verba ads / conteúdo | C26: ='🏠 Painel Geral'!C11 -> 500 | E26: Meta Ads, material gráfico, festival
B27: Eventos / networking | C27: ='🏠 Painel Geral'!C12 -> 150 | E27: Porto Digital, festivais de cinema PE
B28: Subtotal Marketing | C28: =SUM(C26:C27) -> 650
B30: TOTAL GERAL — Mês 5 | C30: =C11+C18+C24+C28 -> 10530
B31: METAS E MARCOS — Mês 5
B32: 📊 Montar deck de pitch para investidor anjo (10–12 slides)
B33: 🔍 Pesquisar lista de investidores anjo de cinema/tech no Brasil
B34: ⚖ Revisar estrutura societária e cap table com contador/advogado
B35: 📦 Organizar Data Room Tier 1 (pitch deck, one-pager, demo)
B37: 🟡 Amarelo = input editável no Painel Geral 🟢 Verde = valor referenciado do Painel 🔵 Azul = fórmula calculada

Sheet 📅 Mês 6
B2: GLAUBER — MÊS 6
B3: Foco: Pitch para investidor anjo — métricas e dados de uso reais
B5: EQUIPE — FOLHA DE PAGAMENTO
B6: Pró-labore sócio 1 | C6: ='🏠 Painel Geral'!C7 -> 2500 | E6: Retirada mensal do sócio fundador. Sujeito a INSS
B7: Pró-labore sócio 2 | C7: ='🏠 Painel Geral'!C7 -> 2500 | E7: Retirada mensal do co-fundador. Sujeito a INSS
B8: Desenvolvedor (freela/júnior) | C8: ='🏠 Painel Geral'!C9 -> 2000 | E8: Terceira pessoa — produto e código
B9: Estagiário / marketing | C9: ='🏠 Painel Geral'!C10 -> 800 | E9: Redes sociais, conteúdo e suporte às produtoras
B10: INSS pró-labore (11%) | C10: ='🏠 Painel Geral'!C7*'🏠 Painel Geral'!C8*0.11 -> 550 | E10: Encargo patronal sobre pró-labore
B11: Subtotal Equipe | C11: =SUM(C6:C10) -> 8350
B12: INFRAESTRUTURA & PRODUTO
B13: Servidor / Nuvem | C13: ='🏠 Painel Geral'!C13 -> 300 | E13: AWS / Vercel / Fly.io
B14: Banco de dados gerenciado | C14: ='🏠 Painel Geral'!C14 -> 100 | E14: PostgreSQL RDS ou Supabase
B15: Storage (vídeos/assets) | C15: ='🏠 Painel Geral'!C15 -> 80 | E15: S3 — arquivos das produtoras
B16: Ferramentas (Notion/Figma) | C16: ='🏠 Painel Geral'!C16 -> 150 | E16: Produtividade, design, CI/CD
B17: Email transacional | C17: ='🏠 Painel Geral'!C17 -> 50 | E17: Resend ou Amazon SES
B18: Subtotal Infra | C18: =SUM(C13:C17) -> 680
B19: ADMINISTRATIVO / JURÍDICO / FISCAL
B20: Contador mensal | C20: ='🏠 Painel Geral'!C18 -> 450 | E20: DAS, folha, obrigações acessórias
B21: DAS Simples Nacional | C21: ='🏠 Painel Geral'!C19 -> 150 | E21: Guia mensal de impostos (estimativa)
B22: Domínio + landing page | C22: ='🏠 Painel Geral'!C20 -> 50 | E22: Registro .com.br + hospedagem
B23: Coworking / end. fiscal | C23: ='🏠 Painel Geral'!C21 -> 200 | E23: Endereço Recife + sala de reunião
B24: Subtotal Admin | C24: =SUM(C20:C23) -> 850
B25: MARKETING & VALIDAÇÃO
B26: Verba ads / conteúdo | C26: ='🏠 Painel Geral'!C11 -> 500 | E26: Meta Ads, material gráfico, festival
B27: Eventos / networking | C27: ='🏠 Painel Geral'!C12 -> 150 | E27: Porto Digital, festivais de cinema PE
B28: Subtotal Marketing | C28: =SUM(C26:C27) -> 650
B30: TOTAL GERAL — Mês 6 | C30: =C11+C18+C24+C28 -> 10530
B31: METAS E MARCOS — Mês 6
B32: 🤝 Iniciar conversas paralelas com ≥5 investidores anjo (funil B2B)
B33: 📈 Apresentar dados reais: usuários, projetos, NPS, feedback
B34: 💼 Due diligence: CNDs limpas, contratos organizados
B35: 🚀 Fechar rodada anjo — meta: R$50k–R$500k
B37: 🟡 Amarelo = input editável no Painel Geral 🟢 Verde = valor referenciado do Painel 🔵 Azul = fórmula calculada

Sheet 📖 Explicações
B2: GLOSSÁRIO E EXPLICAÇÕES — ORÇAMENTO GLAUBER
B5: FINANCEIRO / CAPTAÇÃO
B6: Bootstrapping | C6: Financiar a startup com recursos próprios dos sócios, sem investimento externo. Demonstra comprometimento e não dilui o capital social.
B7: FFF — Friends, Family & Fools | C7: Captação com pessoas próximas que acreditam no projeto. Formalizar com contrato de mútuo simples para evitar conflitos futuros.
B8: Crowdfunding (Catarse / Kickante) | C8: Financiamento coletivo via plataformas. Para o Glauber, use a Catarse (foco em cultura e cinema). Valida o mercado e gera early adopters.
B9: Investidor Anjo | C9: Pessoa física que investe capital (geralmente R$50k–R$500k) em startups early stage em troca de participação societária (equity). Além do dinheiro, traz mentoria e rede de contatos (smart money).
B10: Runway | C10: Quantos meses a startup consegue operar com o capital disponível antes de ficar sem caixa. Meta: chegar ao anjo com pelo menos 6 meses de runway.
B11: Default Dead vs. Default Alive | C11: Default Dead: o caixa acabará antes do break-even → posição fraca na negociação. Default Alive: o crescimento garante break-even antes do fim do caixa → fundador mantém controle da negociação.
B12: Capital Não-Dilutivo | C12: Recursos que não exigem cessão de participação (equity): bootstrapping, subvenções (FINEP, FACEPE), fomento direto. Ideal nas fases iniciais.
B13: Capital Dilutivo | C13: Recursos em troca de equity: investimento anjo, seed, VC. Use apenas após validar o modelo de negócio para não comprometer o cap table nas fases incertas.
B14: Cap Table | C14: Tabela de capitalização — mostra quem possui quanto da empresa. Regra de ouro: não ceder mais de 10–15% nas rodadas iniciais para não inviabilizar rodadas futuras (Série A+).
B15: Smart Money | C15: Investidor que, além do capital, agrega networking, governança e experiência no setor. Para o Glauber, buscar anjos com experiência no mercado audiovisual ou SaaS B2B.
B18: TRIBUTÁRIO / JURÍDICO
B19: Simples Nacional | C19: Regime tributário simplificado para ME e EPP. O DAS (Documento de Arrecadação do Simples) unifica todos os impostos em uma guia mensal.
B20: Fator R | C20: Regra do Simples para empresas de serviços: se a folha de pagamento (pró-labore + CLT) for ≥ 28% do faturamento → Anexo III (alíquota inicial 6%). Se < 28% → Anexo V (alíquota inicial 15,5%). Planeje o pró-labore!
B21: Pró-labore | C21: Remuneração dos sócios pelo trabalho na empresa (≠ distribuição de lucros). Incide INSS (11% do sócio + 11% da empresa). É a base de cálculo do Fator R.
B22: INSS sobre pró-labore | C22: Contribuição previdenciária: 11% descontado do pró-labore do sócio. Obrigatório para garantir direitos previdenciários (aposentadoria, auxílio-doença).
B23: DAS | C23: Documento de Arrecadação do Simples Nacional — guia mensal unificada de impostos. Valor estimado inicial (~R$150) para faturamento de ~R$3k/mês.
B24: JUCEPE | C24: Junta Comercial do Estado de Pernambuco. Portal online para abertura de empresas integrado à Redesim. Prazo médio: 3–5 dias úteis.
B25: CNPJ LTDA | C25: Cadastro Nacional de Pessoa Jurídica — Sociedade Limitada. Mínimo 2 sócios. Responsabilidade limitada ao capital social. Formato correto para o Glauber (CNAE 6201-5/01 não permite MEI).
B26: CNAE 6201-5/01 | C26: Classificação Nacional de Atividades Econômicas para 'Desenvolvimento de programas de computador sob encomenda'. Não permitido para MEI — obrigatório abrir ME ou EPP.
B27: Certidões Negativas (CNDs) | C27: Documentos que comprovam ausência de débitos fiscais. Essencial: manter CNDs limpas desde o início. CNDs sujas bloqueiam aportes de VC e investidores anjo.
B28: Alvará de Funcionamento | C28: Licença da Prefeitura do Recife. Desenvolvimento de software é atividade de baixo risco → licenciamento simplificado, sem vistoria prévia obrigatória.
B31: PROPRIEDADE INTELECTUAL
B32: INPI | C32: Instituto Nacional da Propriedade Industrial. Órgão responsável pelo registro de marcas no Brasil. Unidade Recife: Av. Jorn. Aníbal Fernandes s/n, Sala 307, Cidade Universitária.
B33: Classificação de Nice (NCL) | C33: Sistema internacional que organiza produtos e serviços em 45 classes. Para o Glauber: Classe 42 (software/SaaS) + Classe 35 (gestão de negócios).
B34: Classe 42 | C34: Serviços tecnológicos e científicos. Inclui SaaS, desenvolvimento de software, concepção de sistemas. Principal classe para registrar o Glauber como plataforma.
B35: Classe 35 | C35: Propaganda, gestão e administração de negócios. Cobre a função do Glauber como ferramenta de gestão de produção cinematográfica.
B36: GRU 389 | C36: Guia de Recolhimento da União com especificação pré-aprovada. Mais simples e barato (R$440 com desconto). Recomendado para o registro do Glauber.
B37: Busca de Anterioridade | C37: Verificação obrigatória antes de depositar o pedido no INPI. Acesse busca.inpi.gov.br e pesquise 'Glauber' nas classes 42 e 35. Evita gastos com marca já registrada.
B40: PRODUTO / MÉTRICAS
B41: Product/Market Fit (PMF) | C41: Momento em que o produto resolve um problema real para um mercado suficientemente grande. 80% das startups não chegam ao PMF. Objetivo dos 6 meses: evidências concretas de PMF com as 3 produtoras.
B42: TAM / SAM / SOM | C42: Tamanho do mercado. TAM = mercado total endereçável. SAM = mercado que você pode atender. SOM = mercado que você realisticamente pode capturar. Essencial para o pitch ao anjo.
B43: Data Room | C43: Repositório organizado de documentos para due diligence. Estrutura em 3 tiers: Tier 1 (livre) → pitch deck, one-pager; Tier 2 (interesse mútuo) → cap table, runway; Tier 3 (NDA) → código-fonte, contratos.
B44: NPS — Net Promoter Score | C44: Métrica de satisfação do cliente (0–10). Pergunta: 'Com que probabilidade você recomendaria o Glauber?' Detratores (0–6), Neutros (7–8), Promotores (9–10). Meta: NPS > 50.
B45: Burn Rate | C45: Quanto a startup gasta por mês. O total mensal calculado neste orçamento é o burn rate do Glauber na fase pré-anjo.
B46: Porto Digital | C46: Parque tecnológico em Recife (Recife Antigo, Santo Amaro, Santo Antônio). Empresas instaladas podem ter ISS reduzido a 2%. Ecossistema de inovação com mentorias, editais e networking.
